---
title: Проблема с исключениями: странно, но факт
tags: C++, OS X
---

Нда... Кажется, Гугловцы и Тролли были правы, когда отказались от использования C++-исключений.

В общем, исключения не ловятся. Всё примитивно: в функторе кидается **std::runtime**, на вызывающей стороне - полиморфный перехват оного по **std::exception**.

```cpp
void update_list() {
    try {
         kernel().supported_formatting_styles(); // Здесь кидатеся std::runtime_error...
    } catch( std::exception const& exc ) {
         // Не знаю почему, но исключение не задерживается здесь...
         report_about_problem( exc.what() ); 
         return;
    }
    // ... а вместо этого благополучно летит дальше...
}
```
В итоге исключение благополучно покидает ВСЕ стеки, и приложение ложится с terminate...

Убейте меня, но причину не вижу. Пробовал всё: и перехват по конкретному типу, и по трём точкам (чтобы игнорировать тип исключения) - не помогает.

Прикол в том, что подобная проблема наблюдается лишь *кое-где*. То есть некоторые исключения прекрасно ловятся, а вот некоторые - ни в какую...
